Workbook

Sheet Turmeric competitors
A1: Google Shopping, 'turmeric tablets', Denver CO, 28 Oct 2026 (sponsored carousel). Servings/day marked ~ are assumed.
A2: # | B2: Brand | C2: Product | D2: Format | E2: Count | F2: Servings (days) | G2: Price $ | H2: Was $ | I2: Price per day $ | J2: Rating | K2: Reviews | L2: Seller | M2: Tier | N2: Lead angle / badges | O2: Look | P2: Notes
A3: 1 | B3: Swanson | C3: Full Spectrum Turmeric 720 mg | D3: Capsule | E3: 30 | F3: 30 | G3: 5.99 | I3: =IF(F3="","",ROUND(G3/F3,2)) | J3: 4.8 | K3: 3k+ | L3: Swanson | M3: Value | N3: Whole root, joint & mobility | O3: Green, busy
A4: 2 | B4: ProHealth | C4: Optimized Curcumin Body & Joint | D4: Capsule | E4: 60 | F4: 60 | G4: 10.2 | H4: 25 | I4: =IF(F4="","",ROUND(G4/F4,2)) | J4: 4.6 | K4: 77 | L4: ProHealth | M4: Value | N4: 59% OFF | O4: Navy + stripe | P4: ~servings
A5: 3 | B5: California Gold Nutrition | C5: Curcumin 95 | D5: Capsule | E5: 30 | F5: 30 | G5: 10.27 | I5: =IF(F5="","",ROUND(G5/F5,2)) | J5: 4.8 | K5: 1k+ | L5: iHerb | M5: Value | N5: 95% curcuminoids | O5: White/gold
A6: 4 | B6: Swanson | C6: Turmeric & Black Pepper | D6: Capsule | E6: 90 | F6: 90 | G6: 13.49 | I6: =IF(F6="","",ROUND(G6/F6,2)) | J6: 4.8 | L6: Swanson | M6: Value | N6: Black pepper | O6: Green | P6: ~servings
A7: 5 | B7: Nature Made | C7: Turmeric 500 mg | D7: Capsule | E7: 60 | F7: 60 | G7: 13.99 | I7: =IF(F7="","",ROUND(G7/F7,2)) | J7: 4.7 | K7: 906 | L7: Nature Made | M7: Value | N7: USP verified, pharmacist recommended | O7: Yellow/green, busy | P7: ~servings
A8: 6 | B8: Nutrition Geeks | C8: Turmeric Tablets 2000 mg | D8: Tablet (pouch) | E8: 120 | F8: 120 | G8: 14.05 | H8: 20 | I8: =IF(F8="","",ROUND(G8/F8,2)) | J8: 4.6 | K8: 4k+ | L8: GNMart (reseller) | M8: Value | N8: Made in UK, 2000 mg, SALE | O8: Yellow/teal pouch | P8: ~servings
A9: 7 | B9: Life Extension | C9: Curcumin Elite | D9: Capsule | E9: 30 | F9: 30 | G9: 14.25 | I9: =IF(F9="","",ROUND(G9/F9,2)) | J9: 4.8 | K9: 3k+ | L9: Life Extension | M9: Value | N9: Up to 45.5x bioavailability | O9: Blue
A10: 8 | B10: NatureWise | C10: Organic Turmeric Curcumin + Ginger | D10: Capsule | E10: 90 | F10: 30 | G10: 15.44 | I10: =IF(F10="","",ROUND(G10/F10,2)) | J10: 4.7 | K10: 9k+ | L10: iHerb | M10: Value | N10: Organic, 2,250 mg/serving | O10: Red/cream
A11: 9 | B11: NOW | C11: Turmeric Curcumin | D11: Capsule | E11: 60 | F11: 45 | G11: 17.14 | I11: =IF(F11="","",ROUND(G11/F11,2)) | J11: 4.8 | K11: 5k+ | L11: iHerb | M11: Value | N11: 95% curcuminoids | O11: Orange/green | P11: ~servings
A12: 10 | B12: Future Kind | C12: Vegan Organic Turmeric | D12: Capsule | E12: 60 | F12: 30 | G12: 19 | I12: =IF(F12="","",ROUND(G12/F12,2)) | J12: 4.4 | K12: 67 | L12: Future Kind | M12: Mid | N12: #1 vegan inflammation (claim-heavy title) | O12: Amber glass, cream label
A13: 11 | B13: Global Healing | C13: Turmeric liquid 2 fl oz | D13: Liquid | G13: 24.95 | I13: =IF(F13="","",ROUND(G13/F13,2)) | J13: 4.7 | K13: 1k+ | L13: Global Healing | M13: Mid | N13: Free gift w/ $75+ | O13: Amber dropper
A14: 12 | B14: Humann | C14: Turmeric Chews | D14: Chew | E14: 30 | F14: 30 | G14: 26.95 | I14: =IF(F14="","",ROUND(G14/F14,2)) | J14: 4.3 | K14: 821 | L14: Humann | M14: Mid | N14: 90-day returns | O14: Red pouch
A15: 13 | B15: Micro Ingredients | C15: Turmeric 1000 mg | D15: Capsule | E15: 120 | F15: 90 | G15: 26.95 | I15: =IF(F15="","",ROUND(G15/F15,2)) | L15: Micro Ingredients | M15: Mid | N15: 95% curcumin | O15: White/orange | P15: ~servings
A16: 14 | B16: Momentous | C16: Turmeric | D16: Capsule | E16: 60 | F16: 30 | G16: 29.99 | H16: 40 | I16: =IF(F16="","",ROUND(G16/F16,2)) | J16: 4.7 | K16: 136 | L16: Momentous | M16: Premium | N16: 25% OFF, 1st order price (subscription) | O16: Minimal white, black type | P16: ~servings
A17: 15 | B17: BulkSupplements | C17: Turmeric Curcumin 1000 mg | D17: Capsule | E17: 240 | F17: 120 | G17: 30.97 | I17: =IF(F17="","",ROUND(G17/F17,2)) | J17: 4.6 | K17: 1k+ | L17: BulkSupplements | M17: Mid | N17: Bulk value | O17: White/orange, loud
A18: 16 | B18: Paleovalley | C18: Organic Turmeric Complex | D18: Capsule | E18: 60 | F18: 30 | G18: 34.99 | I18: =IF(F18="","",ROUND(G18/F18,2)) | J18: 4.9 | K18: 1k+ | L18: Paleovalley | M18: Premium | N18: Organic whole food | O18: Orange label
A19: 17 | B19: BetterVits | C19: Turmeric Complex (black pepper + boswellia) | D19: Capsule | E19: 60 | F19: 30 | G19: 35 | I19: =IF(F19="","",ROUND(G19/F19,2)) | L19: BetterVits | M19: Premium | N19: Free delivery; store rating 3.9/5 | O19: Pastel, white bottle, orange label | P19: ~servings
A20: 18 | B20: Thorne | C20: Curcumin Phytosome 1000 mg | D20: Capsule | E20: 60 | F20: 30 | G20: 36 | I20: =IF(F20="","",ROUND(G20/F20,2)) | J20: 4.8 | K20: 824 | L20: Thorne | M20: Premium | N20: Phytosome (clinical form) | O20: Minimal white
A21: 19 | B21: Thorne | C21: Curcumin Phytosome 1000 mg | D21: Capsule | E21: 120 | F21: 60 | G21: 64 | I21: =IF(F21="","",ROUND(G21/F21,2)) | J21: 4.8 | K21: 2k+ | L21: Thorne | M21: High | N21: Phytosome, big pack | O21: Minimal white
A22: 20 | B22: The Absorption Co. | C22: Curcumin 500 mg | D22: Capsule | E22: 60 | F22: 60 | G22: 36.75 | H22: 49 | I22: =IF(F22="","",ROUND(G22/F22,2)) | L22: Absorption Co. | M22: Premium | N22: 149x higher absorption, SALE | O22: Bold white tub, orange block | P22: ~servings
A23: 21 | B23: NAOMI | C23: Turmeric Curcumin High Potency 1200 mg | D23: Capsule | E23: 60 | F23: 30 | G23: 39.99 | I23: =IF(F23="","",ROUND(G23/F23,2)) | J23: 4.8 | K23: 48 | L23: NAOMI | M23: Premium | N23: #1 in title, 90-day returns, Clinicians' Choice | O23: Black bottle, purple + gold
A24: 22 | B24: Gaia Herbs | C24: Turmeric Supreme Extra Strength | D24: Liquid phyto-cap | E24: 120 | F24: 90 | G24: 49.49 | I24: =IF(F24="","",ROUND(G24/F24,2)) | J24: 4.7 | K24: 1k+ | L24: Gaia | M24: High | N24: Extra strength | O24: Amber + green | P24: ~servings
A25: 23 | B25: Nature's Sunshine | C25: Turmeric Curcumin 1000 mg | D25: Capsule | E25: 60 | F25: 30 | G25: 59.95 | I25: =IF(F25="","",ROUND(G25/F25,2)) | L25: Nature's Sunshine | M25: High | N25: Free delivery, trending | O25: Amber + orange | P25: ~servings
A26: 24 | B26: Vimergy | C26: Curcumin with Turmeric | D26: Capsule | E26: 270 | F26: 135 | G26: 99 | I26: =IF(F26="","",ROUND(G26/F26,2)) | J26: 4.8 | L26: vimergy | M26: High | N26: Big pack | O26: White/orange | P26: ~servings
A27: 25 | B27: Mara Labs | C27: CurcElite + BrocElite bundle | D27: Bundle | G27: 139.98 | I27: =IF(F27="","",ROUND(G27/F27,2)) | L27: Mara Labs | M27: High | N27: Bundle, trending brand | O27: Green/orange
A28: 26 | B28: Noovit (today) | C28: Turmeric Complex | D28: Capsule | E28: 60 | F28: 30 | G28: 40 | I28: =IF(F28="","",ROUND(G28/F28,2)) | L28: noovit.com | M28: Premium | N28: Evidence-graded (planned) | O28: White bottle, orange band | P28: Sub $35, 6-pack $30/bottle

Sheet Turmeric tiers
A1: Tier | B1: Listings | C1: Min price $ | D1: Median price $ | E1: Max price $ | F1: Avg price/day $ | G1: Who | H1: Implication for Noovit
A2: Value | B2: =COUNTIF('Turmeric competitors'!M$3:M$28,A2) | C2: =_xlfn.MINIFS('Turmeric competitors'!G$3:G$28,'Turmeric competitors'!M$3:M$28,A2) | D2: {=MEDIAN(IF('Turmeric competitors'!M$3:M$28=A2,'Turmeric competitors'!G$3:G$28))} | E2: =_xlfn.MAXIFS('Turmeric competitors'!G$3:G$28,'Turmeric competitors'!M$3:M$28,A2) | F2: =IFERROR(ROUND(AVERAGEIFS('Turmeric competitors'!I$3:I$28,'Turmeric competitors'!M$3:M$28,A2),2),"") | G2: Under $15–17, big brands, iHerb, resellers | H2: Don't compete: Supliful landed $11.05
A3: Mid | B3: =COUNTIF('Turmeric competitors'!M$3:M$28,A3) | C3: =_xlfn.MINIFS('Turmeric competitors'!G$3:G$28,'Turmeric competitors'!M$3:M$28,A3) | D3: {=MEDIAN(IF('Turmeric competitors'!M$3:M$28=A3,'Turmeric competitors'!G$3:G$28))} | E3: =_xlfn.MAXIFS('Turmeric competitors'!G$3:G$28,'Turmeric competitors'!M$3:M$28,A3) | F3: =IFERROR(ROUND(AVERAGEIFS('Turmeric competitors'!I$3:I$28,'Turmeric competitors'!M$3:M$28,A3),2),"") | G3: Organic, chews, liquid, bulk | H3: Not our lane
A4: Premium | B4: =COUNTIF('Turmeric competitors'!M$3:M$28,A4) | C4: =_xlfn.MINIFS('Turmeric competitors'!G$3:G$28,'Turmeric competitors'!M$3:M$28,A4) | D4: {=MEDIAN(IF('Turmeric competitors'!M$3:M$28=A4,'Turmeric competitors'!G$3:G$28))} | E4: =_xlfn.MAXIFS('Turmeric competitors'!G$3:G$28,'Turmeric competitors'!M$3:M$28,A4) | F4: =IFERROR(ROUND(AVERAGEIFS('Turmeric competitors'!I$3:I$28,'Turmeric competitors'!M$3:M$28,A4),2),"") | G4: Momentous, Paleovalley, BetterVits, Thorne, Absorption, NAOMI | H4: OUR TIER: $29–40 per bottle, $1.00–1.33/day
A5: High | B5: =COUNTIF('Turmeric competitors'!M$3:M$28,A5) | C5: =_xlfn.MINIFS('Turmeric competitors'!G$3:G$28,'Turmeric competitors'!M$3:M$28,A5) | D5: {=MEDIAN(IF('Turmeric competitors'!M$3:M$28=A5,'Turmeric competitors'!G$3:G$28))} | E5: =_xlfn.MAXIFS('Turmeric competitors'!G$3:G$28,'Turmeric competitors'!M$3:M$28,A5) | F5: =IFERROR(ROUND(AVERAGEIFS('Turmeric competitors'!I$3:I$28,'Turmeric competitors'!M$3:M$28,A5),2),"") | G5: Gaia, Nature's Sunshine, big packs, bundles | H5: Bundles and big packs live here

Sheet Turmeric profit
A1: Turmeric 60 caps via Supliful. Orange cells are inputs: change them and everything recalculates.
A3: Landed cost per bottle, free plan $ (product + shipping + fulfilment + processing) | B3: 11.05
A4: Landed cost per bottle, Pro plan $ | B4: 8
A5: Extra bottle in same order $ (product only, estimate; confirm multi-unit shipping) | B5: 4.05
A6: Stripe fee % | B6: 0.029
A7: Stripe fixed fee per order $ | B7: 0.3
A8: Ad cost to win a new customer $ (estimate) | B8: 18
A9: Supliful Pro monthly fee $ | B9: 69
A11: Pro break-even (bottles per month) | B11: =ROUND(B9/(B3-B4),0)
A13: Offer | B13: Bottles in order | C13: Price per bottle $ | D13: Order revenue $ | E13: Landed cost, free $ | F13: Stripe $ | G13: Profit, free $ | H13: Margin, free | I13: Landed cost, Pro $ | J13: Profit, Pro $ | K13: Margin, Pro | L13: Profit after ad cost (first order, free) $
A14: One-time (today) | B14: 1 | C14: 40 | D14: =B14*C14 | E14: =$B$3+(B14-1)*$B$5 | F14: =ROUND(D14*$B$6+$B$7,2) | G14: =D14-E14-F14 | H14: =G14/D14 | I14: =$B$4+(B14-1)*$B$5 | J14: =D14-I14-F14 | K14: =J14/D14 | L14: =G14-$B$8
A15: One-time (suggested) | B15: 1 | C15: 36 | D15: =B15*C15 | E15: =$B$3+(B15-1)*$B$5 | F15: =ROUND(D15*$B$6+$B$7,2) | G15: =D15-E15-F15 | H15: =G15/D15 | I15: =$B$4+(B15-1)*$B$5 | J15: =D15-I15-F15 | K15: =J15/D15 | L15: =G15-$B$8
A16: Subscribe (today) | B16: 1 | C16: 35 | D16: =B16*C16 | E16: =$B$3+(B16-1)*$B$5 | F16: =ROUND(D16*$B$6+$B$7,2) | G16: =D16-E16-F16 | H16: =G16/D16 | I16: =$B$4+(B16-1)*$B$5 | J16: =D16-I16-F16 | K16: =J16/D16 | L16: =G16-$B$8
A17: Subscribe (suggested) | B17: 1 | C17: 32 | D17: =B17*C17 | E17: =$B$3+(B17-1)*$B$5 | F17: =ROUND(D17*$B$6+$B$7,2) | G17: =D17-E17-F17 | H17: =G17/D17 | I17: =$B$4+(B17-1)*$B$5 | J17: =D17-I17-F17 | K17: =J17/D17 | L17: =G17-$B$8
A18: Subscribe (low) | B18: 1 | C18: 30 | D18: =B18*C18 | E18: =$B$3+(B18-1)*$B$5 | F18: =ROUND(D18*$B$6+$B$7,2) | G18: =D18-E18-F18 | H18: =G18/D18 | I18: =$B$4+(B18-1)*$B$5 | J18: =D18-I18-F18 | K18: =J18/D18 | L18: =G18-$B$8
A19: 3-pack one-time | B19: 3 | C19: 33 | D19: =B19*C19 | E19: =$B$3+(B19-1)*$B$5 | F19: =ROUND(D19*$B$6+$B$7,2) | G19: =D19-E19-F19 | H19: =G19/D19 | I19: =$B$4+(B19-1)*$B$5 | J19: =D19-I19-F19 | K19: =J19/D19 | L19: =G19-$B$8
A20: 6-pack one-time | B20: 6 | C20: 30 | D20: =B20*C20 | E20: =$B$3+(B20-1)*$B$5 | F20: =ROUND(D20*$B$6+$B$7,2) | G20: =D20-E20-F20 | H20: =G20/D20 | I20: =$B$4+(B20-1)*$B$5 | J20: =D20-I20-F20 | K20: =J20/D20 | L20: =G20-$B$8
A21: Supliful suggested retail | B21: 1 | C21: 25.9 | D21: =B21*C21 | E21: =$B$3+(B21-1)*$B$5 | F21: =ROUND(D21*$B$6+$B$7,2) | G21: =D21-E21-F21 | H21: =G21/D21 | I21: =$B$4+(B21-1)*$B$5 | J21: =D21-I21-F21 | K21: =J21/D21 | L21: =G21-$B$8
A23: Notes
A24: Supliful shows $4.05 – $11.05: $4.05 is the product, $11.05 is the all-in cost of one bottle delivered.
A25: Extra bottles in the same order are estimated at the product cost only. Confirm Supliful's multi-unit shipping and update B5.
A26: Ad cost is a placeholder for paid Google Shopping; subscriptions recover it over repeat orders.
A27: Competitor prices from Google Shopping on 28 Oct 2026; they change often.

Sheet Berberine competitors
A1: Google Shopping, 'berberine', Denver CO, 28 Oct 2026 (sponsored carousel, 24 unique listings). ~ = dose or servings assumed from label/usual use; blank = not visible.
A2: # | B2: Brand | C2: Product | D2: Format | E2: Count | F2: Servings (days) | G2: Price $ | H2: Was $ | I2: Price per day $ | J2: Berberine mg/day | K2: $ per 1,000 mg | L2: Rating | M2: Reviews | N2: Seller | O2: Tier | P2: Lead angle / badges | Q2: Look | R2: Notes
A3: 1 | B3: Global Healing | C3: Organic Berberine | D3: Capsule | E3: 60 | F3: 30 | G3: 42.95 | I3: =IF(OR(F3="",G3=""),"",ROUND(G3/F3,2)) | K3: =IF(OR(J3="",I3=""),"",ROUND(I3/J3*1000,2)) | N3: Global Healing | O3: Core | P3: Organic, free gift w/ $75+ | Q3: Amber glass, green label | R3: ~servings
A4: 2 | B4: NAOMI | C4: Himalayan Berberine 500 mg | D4: Capsule | E4: 60 | F4: 30 | G4: 39.99 | I4: =IF(OR(F4="",G4=""),"",ROUND(G4/F4,2)) | J4: 1000 | K4: =IF(OR(J4="",I4=""),"",ROUND(I4/J4*1000,2)) | L4: 4.4 | M4: 704 | N4: NAOMI | O4: Core | P4: 'Award-winning' (Shape Awards badge on image) | Q4: Black bottle, purple + gold | R4: ~2 caps/day
A5: 3 | B5: The Absorption Co. | C5: Berberine, 250 mg per serving | D5: Capsule | E5: 60 | F5: 30 | G5: 31.85 | I5: =IF(OR(F5="",G5=""),"",ROUND(G5/F5,2)) | J5: 250 | K5: =IF(OR(J5="",I5=""),"",ROUND(I5/J5*1000,2)) | L5: 3.1 | M5: 15 | N5: Absorption Co. | O5: Core | P5: '6.2x more absorption' | Q5: White tub, red block | R5: Low stars visible: 3.1
A6: 4 | B6: Vitasy | C6: Compass Berberine HCl | D6: Capsule | E6: 60 | F6: 30 | G6: 34.99 | I6: =IF(OR(F6="",G6=""),"",ROUND(G6/F6,2)) | K6: =IF(OR(J6="",I6=""),"",ROUND(I6/J6*1000,2)) | N6: Vitasy | O6: Core | P6: Free shipping | Q6: White bottle, navy label | R6: ~servings
A7: 5 | B7: GLOV Beauty | C7: Berberine Complex | D7: Capsule (pouch) | E7: 60 | F7: 30 | G7: 34 | I7: =IF(OR(F7="",G7=""),"",ROUND(G7/F7,2)) | K7: =IF(OR(J7="",I7=""),"",ROUND(I7/J7*1000,2)) | N7: Glov Beauty | O7: Core | P7: Beauty brand, lifestyle photo | Q7: Pink pouch | R7: ~servings
A8: 6 | B8: Vitasy | C8: Cortex Berberine HCl | D8: Capsule | E8: 60 | F8: 30 | G8: 34.99 | I8: =IF(OR(F8="",G8=""),"",ROUND(G8/F8,2)) | K8: =IF(OR(J8="",I8=""),"",ROUND(I8/J8*1000,2)) | N8: Vitasy | O8: Core | P8: Free shipping | Q8: Dark navy, minimal | R8: Same seller as #4: two brands
A9: 7 | B9: Jade Supplements | C9: Pure Berberine 1200 mg per serving | D9: Capsule | E9: 60 | F9: 30 | G9: 37.99 | I9: =IF(OR(F9="",G9=""),"",ROUND(G9/F9,2)) | J9: 1200 | K9: =IF(OR(J9="",I9=""),"",ROUND(I9/J9*1000,2)) | N9: Jade | O9: Core | P9: Big dose number | Q9: Teal label | R9: 30-day supply stated
A10: 8 | B10: Terry Naturally | C10: Berberine MetX | D10: Capsule | E10: 60 | F10: 30 | G10: 39.95 | I10: =IF(OR(F10="",G10=""),"",ROUND(G10/F10,2)) | K10: =IF(OR(J10="",I10=""),"",ROUND(I10/J10*1000,2)) | N10: Terry Naturally | O10: Core | P10: Enhanced absorption, vegan | Q10: Blue/red, busy | R10: ~servings
A11: 9 | B11: Thorne | C11: Berberine 500 mg | D11: Capsule | E11: 60 | F11: 30 | G11: 44 | I11: =IF(OR(F11="",G11=""),"",ROUND(G11/F11,2)) | J11: 1000 | K11: =IF(OR(J11="",I11=""),"",ROUND(I11/J11*1000,2)) | L11: 4.7 | M11: 5k+ | N11: Thorne | O11: Core | P11: Clinical brand, 5k+ reviews | Q11: Minimal white, green art | R11: ~2 caps/day
A12: 10 | B12: Thorne | C12: Berberine 200 mg | D12: Capsule | E12: 60 | F12: 30 | G12: 30 | I12: =IF(OR(F12="",G12=""),"",ROUND(G12/F12,2)) | J12: 400 | K12: =IF(OR(J12="",I12=""),"",ROUND(I12/J12*1000,2)) | L12: 4.7 | M12: 761 | N12: Thorne | O12: Core | P12: Lower dose | Q12: Minimal white, green art | R12: ~2 caps/day
A13: 11 | B13: Omre | C13: Berberine (AMPK Support) | D13: Capsule | E13: 60 | F13: 30 | G13: 46.55 | I13: =IF(OR(F13="",G13=""),"",ROUND(G13/F13,2)) | K13: =IF(OR(J13="",I13=""),"",ROUND(I13/J13*1000,2)) | L13: 4.8 | M13: 6 | N13: Omre Co | O13: Core | P13: AMPK science angle | Q13: Amber jar, coral label | R13: ~servings
A14: 12 | B14: Naked Nutrition | C14: Berberine 200 mg | D14: Capsule | E14: 60 | F14: 30 | G14: 24.99 | I14: =IF(OR(F14="",G14=""),"",ROUND(G14/F14,2)) | J14: 400 | K14: =IF(OR(J14="",I14=""),"",ROUND(I14/J14*1000,2)) | L14: 5 | M14: 4 | N14: Naked | O14: Value | P14: HSA/FSA eligible in title | Q14: Maroon label, clear bottle | R14: ~2 caps/day
A15: 13 | B15: Kind Patches | C15: Berberine Patches | D15: Patch | E15: 30 | F15: 30 | G15: 15 | I15: =IF(OR(F15="",G15=""),"",ROUND(G15/F15,2)) | K15: =IF(OR(J15="",I15=""),"",ROUND(I15/J15*1000,2)) | N15: Kind Patches | O15: Value | P15: Format: patch, 30-day returns | Q15: Pouch, pink circle | R15: Weak evidence for patches
A16: 14 | B16: Vitasy | C16: Berberine Patches | D16: Patch | E16: 30 | F16: 30 | G16: 24.99 | I16: =IF(OR(F16="",G16=""),"",ROUND(G16/F16,2)) | K16: =IF(OR(J16="",I16=""),"",ROUND(I16/J16*1000,2)) | N16: Vitasy | O16: Value | P16: Format: patch, free shipping | Q16: Navy pouch
A17: 15 | B17: Midi Health | C17: Berberine+ | D17: Capsule | E17: 60 | F17: 30 | G17: 54.99 | I17: =IF(OR(F17="",G17=""),"",ROUND(G17/F17,2)) | K17: =IF(OR(J17="",I17=""),"",ROUND(I17/J17*1000,2)) | N17: Midi Health | O17: Weight / GLP-1 | P17: 'Weight management, fat burning' on label; buy 3 get 10% off | Q17: Amber, bright orange label | R17: Menopause clinic brand
A18: 16 | B18: SpoiledChild | C18: Metabolism Support with Berberine | D18: Liquid? | G18: 49 | I18: =IF(OR(F18="",G18=""),"",ROUND(G18/F18,2)) | K18: =IF(OR(J18="",I18=""),"",ROUND(I18/J18*1000,2)) | L18: 4.7 | M18: 2k+ | N18: spoiledchild | O18: Weight / GLP-1 | P18: Metabolism | Q18: White bottle on black | R18: Format unclear
A19: 17 | B19: Tonum | C19: Natural Weight Loss | D19: Capsule | G19: 59.99 | I19: =IF(OR(F19="",G19=""),"",ROUND(G19/F19,2)) | K19: =IF(OR(J19="",I19=""),"",ROUND(I19/J19*1000,2)) | N19: Tonum | O19: Weight / GLP-1 | P19: Weight loss in title, 30-day returns | Q19: Cream tub, lifestyle photo
A20: 18 | B20: Happy Mammoth | C20: Ultimate Cravings Control | D20: Capsule | G20: 69.99 | I20: =IF(OR(F20="",G20=""),"",ROUND(G20/F20,2)) | K20: =IF(OR(J20="",I20=""),"",ROUND(I20/J20*1000,2)) | L20: 4.8 | M20: 151 | N20: Happy Mammoth | O20: Weight / GLP-1 | P20: Cravings | Q20: Amber, lifestyle photo
A21: 19 | B21: Clade Protocol | C21: GLP-1 Metabolic | D21: Capsule | E21: 60 | F21: 30 | G21: 69 | I21: =IF(OR(F21="",G21=""),"",ROUND(G21/F21,2)) | K21: =IF(OR(J21="",I21=""),"",ROUND(I21/J21*1000,2)) | N21: Clade | O21: Weight / GLP-1 | P21: 'GLP-1' in name, special offer | Q21: Frosted jar, black lid
A22: 20 | B22: The Absorption Co. | C22: WLP-1 Oral GLP-1 Support | D22: Capsule | G22: 79.2 | H22: 99 | I22: =IF(OR(F22="",G22=""),"",ROUND(G22/F22,2)) | K22: =IF(OR(J22="",I22=""),"",ROUND(I22/J22*1000,2)) | N22: Absorption Co. | O22: Weight / GLP-1 | P22: SALE, 200+ sold last month | Q22: White tub, grid | R22: Same brand as #3 at 2.5x price
A23: 21 | B23: Xymogen | C23: Berberine 1 g per serving | D23: Capsule | E23: 120 | F23: 60 | G23: 86.99 | I23: =IF(OR(F23="",G23=""),"",ROUND(G23/F23,2)) | J23: 1000 | K23: =IF(OR(J23="",I23=""),"",ROUND(I23/J23*1000,2)) | N23: Xymogen | O23: Big pack | P23: Practitioner brand | Q23: Minimal white, blue/orange
A24: 22 | B24: Dr Juan's Santo Remedio | C24: Berberine+ Slim Fit (3-pack) | D24: Capsule | E24: 180 | F24: 90 | G24: 107.86 | I24: =IF(OR(F24="",G24=""),"",ROUND(G24/F24,2)) | K24: =IF(OR(J24="",I24=""),"",ROUND(I24/J24*1000,2)) | L24: 4.3 | M24: 283 | N24: Dr Juan | O24: Big pack | P24: Doctor-led TV brand, 3-pack | Q24: Magenta, busy | R24: ~servings
A25: 23 | B25: Mara Labs | C25: BerbElite | D25: Capsule | E25: 120 | F25: 60 | G25: 109.99 | I25: =IF(OR(F25="",G25=""),"",ROUND(G25/F25,2)) | K25: =IF(OR(J25="",I25=""),"",ROUND(I25/J25*1000,2)) | N25: Mara Labs | O25: Big pack | P25: Bioavailable berberine | Q25: White, gold diamond | R25: ~servings
A26: 24 | B26: AKA Labs | C26: Reduce appetite strips (berberine + saffron) | D26: Oral strip | E26: 30 | F26: 30 | I26: =IF(OR(F26="",G26=""),"",ROUND(G26/F26,2)) | K26: =IF(OR(J26="",I26=""),"",ROUND(I26/J26*1000,2)) | N26: AKA Labs | O26: Value | P26: Format: strip, appetite | Q26: Blue tin | R26: Price cut off in screenshot
A27: 25 | B27: Noovit (Supliful) | C27: Berberine capsules | D27: Capsule | E27: 60 | F27: 30 | G27: 36 | I27: =IF(OR(F27="",G27=""),"",ROUND(G27/F27,2)) | J27: 146 | K27: =IF(OR(J27="",I27=""),"",ROUND(I27/J27*1000,2)) | N27: noovit.com | O27: Core | P27: Evidence-graded (planned) | Q27: Label option B | R27: ~146 mg/day is our estimate from the ingredient list: VERIFY with Supliful

Sheet Berberine tiers
A1: Tier | B1: Listings | C1: Min price $ | D1: Median price $ | E1: Max price $ | F1: Avg price/day $ | G1: Who | H1: Implication for Noovit
A2: Value | B2: =COUNTIF('Berberine competitors'!O$3:O$27,A2) | C2: =_xlfn.MINIFS('Berberine competitors'!G$3:G$27,'Berberine competitors'!O$3:O$27,A2) | D2: {=MEDIAN(IF(('Berberine competitors'!O$3:O$27=A2)*('Berberine competitors'!G$3:G$27<>""),'Berberine competitors'!G$3:G$27))} | E2: =_xlfn.MAXIFS('Berberine competitors'!G$3:G$27,'Berberine competitors'!O$3:O$27,A2) | F2: =IFERROR(ROUND(AVERAGEIFS('Berberine competitors'!I$3:I$27,'Berberine competitors'!O$3:O$27,A2),2),"") | G2: Naked 200 mg, patches, strips | H2: Patches/strips: weak evidence. Naked shows HSA/FSA.
A3: Core | B3: =COUNTIF('Berberine competitors'!O$3:O$27,A3) | C3: =_xlfn.MINIFS('Berberine competitors'!G$3:G$27,'Berberine competitors'!O$3:O$27,A3) | D3: {=MEDIAN(IF(('Berberine competitors'!O$3:O$27=A3)*('Berberine competitors'!G$3:G$27<>""),'Berberine competitors'!G$3:G$27))} | E3: =_xlfn.MAXIFS('Berberine competitors'!G$3:G$27,'Berberine competitors'!O$3:O$27,A3) | F3: =IFERROR(ROUND(AVERAGEIFS('Berberine competitors'!I$3:I$27,'Berberine competitors'!O$3:O$27,A3),2),"") | G3: Thorne, NAOMI, Absorption, Vitasy, GLOV, Jade, Terry, Global Healing, Omre | H3: OUR TIER: plain 60-cap berberine at $30-47, median ~$37
A4: Weight / GLP-1 | B4: =COUNTIF('Berberine competitors'!O$3:O$27,A4) | C4: =_xlfn.MINIFS('Berberine competitors'!G$3:G$27,'Berberine competitors'!O$3:O$27,A4) | D4: {=MEDIAN(IF(('Berberine competitors'!O$3:O$27=A4)*('Berberine competitors'!G$3:G$27<>""),'Berberine competitors'!G$3:G$27))} | E4: =_xlfn.MAXIFS('Berberine competitors'!G$3:G$27,'Berberine competitors'!O$3:O$27,A4) | F4: =IFERROR(ROUND(AVERAGEIFS('Berberine competitors'!I$3:I$27,'Berberine competitors'!O$3:O$27,A4),2),"") | G4: Midi, SpoiledChild, Tonum, Happy Mammoth, Clade, Absorption WLP-1 | H4: Avoid: 'GLP-1' / weight-loss claims are FDA/FTC enforcement targets
A5: Big pack | B5: =COUNTIF('Berberine competitors'!O$3:O$27,A5) | C5: =_xlfn.MINIFS('Berberine competitors'!G$3:G$27,'Berberine competitors'!O$3:O$27,A5) | D5: {=MEDIAN(IF(('Berberine competitors'!O$3:O$27=A5)*('Berberine competitors'!G$3:G$27<>""),'Berberine competitors'!G$3:G$27))} | E5: =_xlfn.MAXIFS('Berberine competitors'!G$3:G$27,'Berberine competitors'!O$3:O$27,A5) | F5: =IFERROR(ROUND(AVERAGEIFS('Berberine competitors'!I$3:I$27,'Berberine competitors'!O$3:O$27,A5),2),"") | G5: Xymogen 120, Dr Juan 3-pack, Mara Labs | H5: Our 3- and 6-packs compete here

Sheet Berberine profit
A1: Berberine 60 caps via Supliful. Orange cells are inputs: change them and everything recalculates.
A3: Landed cost per bottle, free plan $ (product + shipping + fulfilment + processing) | B3: 10.25
A4: Landed cost per bottle, Pro plan $ (ESTIMATE: same ~$3 saving as turmeric; confirm) | B4: 7.2
A5: Extra bottle in same order $ (product only, estimate) | B5: 3.75
A6: Stripe fee % | B6: 0.029
A7: Stripe fixed fee per order $ | B7: 0.3
A8: Ad cost to win a new customer $ (estimate) | B8: 18
A9: Supliful Pro monthly fee $ | B9: 69
A10: Noovit Berberine mg/day | B10: 146
A11: Pro break-even (bottles per month) | B11: =ROUND(B9/(B3-B4),0)
A13: Offer | B13: Bottles in order | C13: Price per bottle $ | D13: Order revenue $ | E13: Landed cost, free $ | F13: Stripe $ | G13: Profit, free $ | H13: Margin, free | I13: Landed cost, Pro $ | J13: Profit, Pro $ | K13: Margin, Pro | L13: Profit after ad cost (first order, free) $ | M13: $ per 1,000 mg
A14: Supliful suggested retail | B14: 1 | C14: 39.9 | D14: =B14*C14 | E14: =$B$3+(B14-1)*$B$5 | F14: =ROUND(D14*$B$6+$B$7,2) | G14: =D14-E14-F14 | H14: =G14/D14 | I14: =$B$4+(B14-1)*$B$5 | J14: =D14-I14-F14 | K14: =J14/D14 | L14: =G14-$B$8 | M14: =ROUND(C14/30/$B$10*1000,2)
A15: One-time (catalog today) | B15: 1 | C15: 40 | D15: =B15*C15 | E15: =$B$3+(B15-1)*$B$5 | F15: =ROUND(D15*$B$6+$B$7,2) | G15: =D15-E15-F15 | H15: =G15/D15 | I15: =$B$4+(B15-1)*$B$5 | J15: =D15-I15-F15 | K15: =J15/D15 | L15: =G15-$B$8 | M15: =ROUND(C15/30/$B$10*1000,2)
A16: One-time (suggested) | B16: 1 | C16: 36 | D16: =B16*C16 | E16: =$B$3+(B16-1)*$B$5 | F16: =ROUND(D16*$B$6+$B$7,2) | G16: =D16-E16-F16 | H16: =G16/D16 | I16: =$B$4+(B16-1)*$B$5 | J16: =D16-I16-F16 | K16: =J16/D16 | L16: =G16-$B$8 | M16: =ROUND(C16/30/$B$10*1000,2)
A17: Subscribe (suggested) | B17: 1 | C17: 32 | D17: =B17*C17 | E17: =$B$3+(B17-1)*$B$5 | F17: =ROUND(D17*$B$6+$B$7,2) | G17: =D17-E17-F17 | H17: =G17/D17 | I17: =$B$4+(B17-1)*$B$5 | J17: =D17-I17-F17 | K17: =J17/D17 | L17: =G17-$B$8 | M17: =ROUND(C17/30/$B$10*1000,2)
A18: Low (if dose stays ~146 mg) | B18: 1 | C18: 29 | D18: =B18*C18 | E18: =$B$3+(B18-1)*$B$5 | F18: =ROUND(D18*$B$6+$B$7,2) | G18: =D18-E18-F18 | H18: =G18/D18 | I18: =$B$4+(B18-1)*$B$5 | J18: =D18-I18-F18 | K18: =J18/D18 | L18: =G18-$B$8 | M18: =ROUND(C18/30/$B$10*1000,2)
A19: 3-pack one-time | B19: 3 | C19: 32 | D19: =B19*C19 | E19: =$B$3+(B19-1)*$B$5 | F19: =ROUND(D19*$B$6+$B$7,2) | G19: =D19-E19-F19 | H19: =G19/D19 | I19: =$B$4+(B19-1)*$B$5 | J19: =D19-I19-F19 | K19: =J19/D19 | L19: =G19-$B$8 | M19: =ROUND(C19/30/$B$10*1000,2)
A20: 6-pack one-time | B20: 6 | C20: 29 | D20: =B20*C20 | E20: =$B$3+(B20-1)*$B$5 | F20: =ROUND(D20*$B$6+$B$7,2) | G20: =D20-E20-F20 | H20: =G20/D20 | I20: =$B$4+(B20-1)*$B$5 | J20: =D20-I20-F20 | K20: =J20/D20 | L20: =G20-$B$8 | M20: =ROUND(C20/30/$B$10*1000,2)
A23: Per-mg comparison: price per bottle Noovit would need to match each competitor's $ per 1,000 mg (at B10 mg/day, 30 days per bottle)
A24: Competitor | B24: Their mg/day | C24: Their price/day $ | D24: Their $ per 1,000 mg | E24: Noovit price to match $
A25: ='Berberine competitors'!B4&" – "&'Berberine competitors'!C4 | B25: ='Berberine competitors'!J4 | C25: ='Berberine competitors'!I4 | D25: ='Berberine competitors'!K4 | E25: =ROUND(D25/1000*$B$10*30,2)
A26: ='Berberine competitors'!B5&" – "&'Berberine competitors'!C5 | B26: ='Berberine competitors'!J5 | C26: ='Berberine competitors'!I5 | D26: ='Berberine competitors'!K5 | E26: =ROUND(D26/1000*$B$10*30,2)
A27: ='Berberine competitors'!B9&" – "&'Berberine competitors'!C9 | B27: ='Berberine competitors'!J9 | C27: ='Berberine competitors'!I9 | D27: ='Berberine competitors'!K9 | E27: =ROUND(D27/1000*$B$10*30,2)
A28: ='Berberine competitors'!B11&" – "&'Berberine competitors'!C11 | B28: ='Berberine competitors'!J11 | C28: ='Berberine competitors'!I11 | D28: ='Berberine competitors'!K11 | E28: =ROUND(D28/1000*$B$10*30,2)
A29: ='Berberine competitors'!B12&" – "&'Berberine competitors'!C12 | B29: ='Berberine competitors'!J12 | C29: ='Berberine competitors'!I12 | D29: ='Berberine competitors'!K12 | E29: =ROUND(D29/1000*$B$10*30,2)
A30: ='Berberine competitors'!B14&" – "&'Berberine competitors'!C14 | B30: ='Berberine competitors'!J14 | C30: ='Berberine competitors'!I14 | D30: ='Berberine competitors'!K14 | E30: =ROUND(D30/1000*$B$10*30,2)
A31: ='Berberine competitors'!B23&" – "&'Berberine competitors'!C23 | B31: ='Berberine competitors'!J23 | C31: ='Berberine competitors'!I23 | D31: ='Berberine competitors'!K23 | E31: =ROUND(D31/1000*$B$10*30,2)
A33: Notes
A34: Supliful shows $3.75 – $10.25: $3.75 is the product, $10.25 the all-in cost of one bottle delivered. Suggested retail $39.90.
A35: DOSE CHECK: Supliful lists 790 mg Berberine HCl extract 8% + 10 mg extract 97% per capsule. If the % is berberine, that is ~73 mg/capsule, ~146 mg/day (B10).
A36: At ~146 mg/day we are the MOST EXPENSIVE per mg in the grid: ~$8.22 per 1,000 mg at $36 vs $1.06–4.25 for competitors. Matching Thorne 500 mg per mg would mean ~$6.40 a bottle.
A37: Studies use 900–1,500 mg/day; competitors sell 400–1,200 mg/day. Ask Supliful for the Supplement Facts/COA before pricing or launching. Change B10 when confirmed.
A38: Competitor prices from Google Shopping on 28 Oct 2026; they change often.

Sheet Lion's Mane competitors
A1: Google Shopping, 'lion's mane mushroom supplement', Denver CO, 28 Oct 2026 (sponsored carousel, 20 listings). mg/day = mushroom powder or extract as labelled (extracts are not 1:1 with powder). ~ = assumed.
A2: # | B2: Brand | C2: Product | D2: Format | E2: Count | F2: Servings (days) | G2: Price $ | H2: Was $ | I2: Price per day $ | J2: Lion's mane mg/day | K2: $ per 1,000 mg | L2: Rating | M2: Reviews | N2: Seller | O2: Tier | P2: Lead angle / badges | Q2: Look | R2: Notes
A3: 1 | B3: Vitasy | C3: Cortex Lion's Mane Mushroom 1000 mg | D3: Capsule | E3: 60 | F3: 30 | G3: 44.99 | I3: =IF(OR(F3="",G3=""),"",ROUND(G3/F3,2)) | J3: 1000 | K3: =IF(OR(J3="",I3=""),"",ROUND(I3/J3*1000,2)) | N3: Vitasy | O3: Core | P3: Supports memory, focus & brain health; free shipping | Q3: Dark navy, minimal | R3: ~2 caps/day
A4: 2 | B4: Brainstorm Nutrition | C4: Lion's Mane Mushroom 1000 mg | D4: Capsule | E4: 60 | F4: 30 | G4: 34.99 | I4: =IF(OR(F4="",G4=""),"",ROUND(G4/F4,2)) | J4: 1000 | K4: =IF(OR(J4="",I4=""),"",ROUND(I4/J4*1000,2)) | N4: Brainstorm | O4: Core | P4: Focus, clarity, performance | Q4: Grey label, mountain art | R4: ~2 caps/day
A5: 3 | B5: Eversio Wellness | C5: Lion's Mane 8:1 dual extract, 500 mg | D5: Capsule | E5: 60 | F5: 60 | G5: 49.99 | I5: =IF(OR(F5="",G5=""),"",ROUND(G5/F5,2)) | J5: 500 | K5: =IF(OR(J5="",I5=""),"",ROUND(I5/J5*1000,2)) | L5: 4.9 | M5: 296 | N5: Eversio | O5: Core | P5: Dual extract (water + alcohol), 8:1 | Q5: Amber jar, bold blue label | R5: Extract: ~4 g mushroom equivalent; ~1 cap/day
A6: 4 | B6: Future Kind | C6: Vegan Lion's Mane Mushroom Complex | D6: Capsule | E6: 60 | F6: 30 | I6: =IF(OR(F6="",G6=""),"",ROUND(G6/F6,2)) | K6: =IF(OR(J6="",I6=""),"",ROUND(I6/J6*1000,2)) | L6: 4.6 | M6: 129 | N6: Future Kind | O6: Core | P6: Vegan | Q6: Amber, blush label | R6: Price cut off
A7: 5 | B7: 3rd Planet | C7: MycoRev Neuro (via Aduco) | D7: Capsule | E7: 60 | F7: 30 | G7: 58.5 | I7: =IF(OR(F7="",G7=""),"",ROUND(G7/F7,2)) | K7: =IF(OR(J7="",I7=""),"",ROUND(I7/J7*1000,2)) | N7: Aduco | O7: Core | P7: 'Professional grade neurological support' | Q7: Amber, white label | R7: ~servings
A8: 6 | B8: SuperFeast | C8: Lion's Mane mushroom extract powder 100 g | D8: Powder | E8: 100 | F8: 50 | G8: 61 | I8: =IF(OR(F8="",G8=""),"",ROUND(G8/F8,2)) | J8: 2000 | K8: =IF(OR(J8="",I8=""),"",ROUND(I8/J8*1000,2)) | L8: 4.8 | M8: 286 | N8: SuperFeast | O8: Core | P8: Dual-extracted, Australian brand | Q8: Black Miron glass jar, minimal | R8: ~2 g/day
A9: 7 | B9: Feral Fungi | C9: Lion's Mane tincture | D9: Tincture | G9: 100 | I9: =IF(OR(F9="",G9=""),"",ROUND(G9/F9,2)) | K9: =IF(OR(J9="",I9=""),"",ROUND(I9/J9*1000,2)) | N9: Feral Fungi | O9: High | P9: 20% off $500+ | Q9: Amber dropper, real mushroom photo
A10: 8 | B10: Sunmed | C10: 10 Mushroom all-in-one gummies | D10: Gummy | E10: 60 | F10: 30 | G10: 34 | I10: =IF(OR(F10="",G10=""),"",ROUND(G10/F10,2)) | K10: =IF(OR(J10="",I10=""),"",ROUND(I10/J10*1000,2)) | N10: Sunmed | O10: Blend / other | P10: 10 mushrooms | Q10: Pouch, pastel
A11: 9 | B11: Auri Nutrition | C11: Super Mushroom Focus Gummies | D11: Gummy | E11: 60 | F11: 30 | G11: 55 | I11: =IF(OR(F11="",G11=""),"",ROUND(G11/F11,2)) | J11: 250 | K11: =IF(OR(J11="",I11=""),"",ROUND(I11/J11*1000,2)) | L11: 3.8 | N11: Auri | O11: Blend / other | P11: Lion's mane + alpha GPC + rhodiola | Q11: Black/white pouch | R11: 250 mg lion's mane per serving
A12: 10 | B12: First Person | C12: Moonlight mushroom capsules | D12: Capsule (tin) | G12: 50 | I12: =IF(OR(F12="",G12=""),"",ROUND(G12/F12,2)) | K12: =IF(OR(J12="",I12=""),"",ROUND(I12/J12*1000,2)) | N12: First Person | O12: Nootropic brand | P12: Design-led tin | Q12: Lavender tin, capsules shown | R12: Free by 11/10
A13: 11 | B13: Innerbody Labs | C13: Focus Support (multi-month) | D13: Capsule | E13: 120 | G13: 267 | I13: =IF(OR(F13="",G13=""),"",ROUND(G13/F13,2)) | K13: =IF(OR(J13="",I13=""),"",ROUND(I13/J13*1000,2)) | N13: Innerbody Labs | O13: Nootropic brand | P13: Special offer; ingredients 'supported by human research' | Q13: Amber + white minimal | R13: Likely multi-bottle pack
A14: 12 | B14: Magic Mind | C14: Mental performance shots (box) | D14: Shot | G14: 357 | I14: =IF(OR(F14="",G14=""),"",ROUND(G14/F14,2)) | K14: =IF(OR(J14="",I14=""),"",ROUND(I14/J14*1000,2)) | L14: 4.5 | M14: 1k+ | N14: Magic Mind | O14: Nootropic brand | P14: Bulk box | Q14: Pastel box, wave art
A15: 13 | B15: Magic Mind | C15: Mental performance shots (box) | D15: Shot | G15: 178.5 | I15: =IF(OR(F15="",G15=""),"",ROUND(G15/F15,2)) | K15: =IF(OR(J15="",I15=""),"",ROUND(I15/J15*1000,2)) | N15: Magic Mind | O15: Nootropic brand | P15: Trending | Q15: Pastel box, wave art
A16: 14 | B16: Magic Mind | C16: MAXX high-caffeine shot | D16: Shot | G16: 44.63 | I16: =IF(OR(F16="",G16=""),"",ROUND(G16/F16,2)) | K16: =IF(OR(J16="",I16=""),"",ROUND(I16/J16*1000,2)) | L16: 4.1 | M16: 152 | N16: Magic Mind | O16: Nootropic brand | P16: 10+ clinically backed ingredients | Q16: Green bottle
A17: 15 | B17: Magic Mind | C17: Original nootropic energy shot | D17: Shot | G17: 44.63 | I17: =IF(OR(F17="",G17=""),"",ROUND(G17/F17,2)) | K17: =IF(OR(J17="",I17=""),"",ROUND(I17/J17*1000,2)) | N17: Magic Mind | O17: Nootropic brand | P17: Trending brand | Q17: Green bottle, orange label
A18: 16 | B18: Graymatter | C18: Bright Mind nootropic drink mix | D18: Powder (pouch) | E18: 48 | F18: 48 | G18: 39.34 | H18: 47 | I18: =IF(OR(F18="",G18=""),"",ROUND(G18/F18,2)) | K18: =IF(OR(J18="",I18=""),"",ROUND(I18/J18*1000,2)) | N18: Graymatter | O18: Nootropic brand | P18: SALE, superfood cognitive support | Q18: White pouch, red accent
A19: 17 | B19: Erth Labs | C19: Adaptogenic superfood brew | D19: Powder | G19: 27 | I19: =IF(OR(F19="",G19=""),"",ROUND(G19/F19,2)) | K19: =IF(OR(J19="",I19=""),"",ROUND(I19/J19*1000,2)) | N19: Erth Labs | O19: Blend / other | P19: Coffee alternative | Q19: Kraft pouches, lifestyle
A20: 18 | B20: Manna Vitality | C20: Beta Glucan | D20: Capsule | E20: 60 | G20: 99 | I20: =IF(OR(F20="",G20=""),"",ROUND(G20/F20,2)) | K20: =IF(OR(J20="",I20=""),"",ROUND(I20/J20*1000,2)) | L20: 4.4 | M20: 10 | N20: Manna | O20: High | P20: Immune, cellular protection | Q20: Black + gold | R20: Off-topic
A21: 19 | B21: Broc Shot | C21: Sulforaphane capsules | D21: Capsule | G21: 119.99 | I21: =IF(OR(F21="",G21=""),"",ROUND(G21/F21,2)) | K21: =IF(OR(J21="",I21=""),"",ROUND(I21/J21*1000,2)) | L21: 4.6 | M21: 153 | N21: Broc Shot | O21: High | P21: Sulforaphane | Q21: Green tin | R21: Off-topic
A22: 20 | B22: Noovit (Supliful) | C22: Lion's Mane mushroom capsules | D22: Capsule | E22: 60 | F22: 30 | G22: 40 | I22: =IF(OR(F22="",G22=""),"",ROUND(G22/F22,2)) | J22: 1000 | K22: =IF(OR(J22="",I22=""),"",ROUND(I22/J22*1000,2)) | N22: noovit.com | O22: Core | P22: Organic, evidence-graded (planned) | Q22: Label option B | R22: 1,000 mg fruiting body + mycelium powder, 40% polysaccharides

Sheet Lion's Mane tiers
A1: Tier | B1: Listings | C1: Min price $ | D1: Median price $ | E1: Max price $ | F1: Avg price/day $ | G1: Who | H1: Implication for Noovit
A2: Core | B2: =COUNTIF('Lion''s Mane competitors'!O$3:O$22,A2) | C2: =_xlfn.MINIFS('Lion''s Mane competitors'!G$3:G$22,'Lion''s Mane competitors'!O$3:O$22,A2) | D2: {=MEDIAN(IF(('Lion''s Mane competitors'!O$3:O$22=A2)*('Lion''s Mane competitors'!G$3:G$22<>""),'Lion''s Mane competitors'!G$3:G$22))} | E2: =_xlfn.MAXIFS('Lion''s Mane competitors'!G$3:G$22,'Lion''s Mane competitors'!O$3:O$22,A2) | F2: =IFERROR(ROUND(AVERAGEIFS('Lion''s Mane competitors'!I$3:I$22,'Lion''s Mane competitors'!O$3:O$22,A2),2),"") | G2: Cortex, Brainstorm, Eversio, Future Kind, 3rd Planet, SuperFeast | H2: OUR TIER: plain lion's mane at $35–61, median ~$47
A3: Nootropic brand | B3: =COUNTIF('Lion''s Mane competitors'!O$3:O$22,A3) | C3: =_xlfn.MINIFS('Lion''s Mane competitors'!G$3:G$22,'Lion''s Mane competitors'!O$3:O$22,A3) | D3: {=MEDIAN(IF(('Lion''s Mane competitors'!O$3:O$22=A3)*('Lion''s Mane competitors'!G$3:G$22<>""),'Lion''s Mane competitors'!G$3:G$22))} | E3: =_xlfn.MAXIFS('Lion''s Mane competitors'!G$3:G$22,'Lion''s Mane competitors'!O$3:O$22,A3) | F3: =IFERROR(ROUND(AVERAGEIFS('Lion''s Mane competitors'!I$3:I$22,'Lion''s Mane competitors'!O$3:O$22,A3),2),"") | G3: Magic Mind, Graymatter, Innerbody Labs, First Person | H3: Brand/aesthetic reference; they sell blends and shots, not single mushrooms
A4: Blend / other | B4: =COUNTIF('Lion''s Mane competitors'!O$3:O$22,A4) | C4: =_xlfn.MINIFS('Lion''s Mane competitors'!G$3:G$22,'Lion''s Mane competitors'!O$3:O$22,A4) | D4: {=MEDIAN(IF(('Lion''s Mane competitors'!O$3:O$22=A4)*('Lion''s Mane competitors'!G$3:G$22<>""),'Lion''s Mane competitors'!G$3:G$22))} | E4: =_xlfn.MAXIFS('Lion''s Mane competitors'!G$3:G$22,'Lion''s Mane competitors'!O$3:O$22,A4) | F4: =IFERROR(ROUND(AVERAGEIFS('Lion''s Mane competitors'!I$3:I$22,'Lion''s Mane competitors'!O$3:O$22,A4),2),"") | G4: Sunmed, Auri gummies, Erth brew | H4: Gummies and brews: a later format option
A5: High | B5: =COUNTIF('Lion''s Mane competitors'!O$3:O$22,A5) | C5: =_xlfn.MINIFS('Lion''s Mane competitors'!G$3:G$22,'Lion''s Mane competitors'!O$3:O$22,A5) | D5: {=MEDIAN(IF(('Lion''s Mane competitors'!O$3:O$22=A5)*('Lion''s Mane competitors'!G$3:G$22<>""),'Lion''s Mane competitors'!G$3:G$22))} | E5: =_xlfn.MAXIFS('Lion''s Mane competitors'!G$3:G$22,'Lion''s Mane competitors'!O$3:O$22,A5) | F5: =IFERROR(ROUND(AVERAGEIFS('Lion''s Mane competitors'!I$3:I$22,'Lion''s Mane competitors'!O$3:O$22,A5),2),"") | G5: Feral Fungi tincture, off-topic (beta glucan, sulforaphane) | H5: Ignore

Sheet Lion's Mane profit
A1: Lion's Mane 60 caps via Supliful. Orange cells are inputs: change them and everything recalculates.
A3: Landed cost per bottle, free plan $ (PLACEHOLDER: send Supliful's lion's mane price) | B3: 11
A4: Landed cost per bottle, Pro plan $ (PLACEHOLDER) | B4: 8
A5: Extra bottle in same order $ (product only, PLACEHOLDER) | B5: 4
A6: Stripe fee % | B6: 0.029
A7: Stripe fixed fee per order $ | B7: 0.3
A8: Ad cost to win a new customer $ (estimate) | B8: 18
A9: Supliful Pro monthly fee $ | B9: 69
A10: Noovit Lion's mane mg/day | B10: 1000
A11: Pro break-even (bottles per month) | B11: =ROUND(B9/(B3-B4),0)
A13: Offer | B13: Bottles in order | C13: Price per bottle $ | D13: Order revenue $ | E13: Landed cost, free $ | F13: Stripe $ | G13: Profit, free $ | H13: Margin, free | I13: Landed cost, Pro $ | J13: Profit, Pro $ | K13: Margin, Pro | L13: Profit after ad cost (first order, free) $ | M13: $ per 1,000 mg
A14: One-time (catalog today) | B14: 1 | C14: 35 | D14: =B14*C14 | E14: =$B$3+(B14-1)*$B$5 | F14: =ROUND(D14*$B$6+$B$7,2) | G14: =D14-E14-F14 | H14: =G14/D14 | I14: =$B$4+(B14-1)*$B$5 | J14: =D14-I14-F14 | K14: =J14/D14 | L14: =G14-$B$8 | M14: =ROUND(C14/30/$B$10*1000,2)
A15: One-time (suggested) | B15: 1 | C15: 40 | D15: =B15*C15 | E15: =$B$3+(B15-1)*$B$5 | F15: =ROUND(D15*$B$6+$B$7,2) | G15: =D15-E15-F15 | H15: =G15/D15 | I15: =$B$4+(B15-1)*$B$5 | J15: =D15-I15-F15 | K15: =J15/D15 | L15: =G15-$B$8 | M15: =ROUND(C15/30/$B$10*1000,2)
A16: One-time (high) | B16: 1 | C16: 44 | D16: =B16*C16 | E16: =$B$3+(B16-1)*$B$5 | F16: =ROUND(D16*$B$6+$B$7,2) | G16: =D16-E16-F16 | H16: =G16/D16 | I16: =$B$4+(B16-1)*$B$5 | J16: =D16-I16-F16 | K16: =J16/D16 | L16: =G16-$B$8 | M16: =ROUND(C16/30/$B$10*1000,2)
A17: Subscribe (suggested) | B17: 1 | C17: 35 | D17: =B17*C17 | E17: =$B$3+(B17-1)*$B$5 | F17: =ROUND(D17*$B$6+$B$7,2) | G17: =D17-E17-F17 | H17: =G17/D17 | I17: =$B$4+(B17-1)*$B$5 | J17: =D17-I17-F17 | K17: =J17/D17 | L17: =G17-$B$8 | M17: =ROUND(C17/30/$B$10*1000,2)
A18: 3-pack one-time | B18: 3 | C18: 36 | D18: =B18*C18 | E18: =$B$3+(B18-1)*$B$5 | F18: =ROUND(D18*$B$6+$B$7,2) | G18: =D18-E18-F18 | H18: =G18/D18 | I18: =$B$4+(B18-1)*$B$5 | J18: =D18-I18-F18 | K18: =J18/D18 | L18: =G18-$B$8 | M18: =ROUND(C18/30/$B$10*1000,2)
A19: 6-pack one-time | B19: 6 | C19: 33 | D19: =B19*C19 | E19: =$B$3+(B19-1)*$B$5 | F19: =ROUND(D19*$B$6+$B$7,2) | G19: =D19-E19-F19 | H19: =G19/D19 | I19: =$B$4+(B19-1)*$B$5 | J19: =D19-I19-F19 | K19: =J19/D19 | L19: =G19-$B$8 | M19: =ROUND(C19/30/$B$10*1000,2)
A22: Per-mg comparison: price per bottle Noovit would need to match each competitor's $ per 1,000 mg (at B10 mg/day, 30 days per bottle)
A23: Competitor | B23: Their mg/day | C23: Their price/day $ | D23: Their $ per 1,000 mg | E23: Noovit price to match $
A24: ='Lion''s Mane competitors'!B3&" – "&'Lion''s Mane competitors'!C3 | B24: ='Lion''s Mane competitors'!J3 | C24: ='Lion''s Mane competitors'!I3 | D24: ='Lion''s Mane competitors'!K3 | E24: =ROUND(D24/1000*$B$10*30,2)
A25: ='Lion''s Mane competitors'!B4&" – "&'Lion''s Mane competitors'!C4 | B25: ='Lion''s Mane competitors'!J4 | C25: ='Lion''s Mane competitors'!I4 | D25: ='Lion''s Mane competitors'!K4 | E25: =ROUND(D25/1000*$B$10*30,2)
A26: ='Lion''s Mane competitors'!B5&" – "&'Lion''s Mane competitors'!C5 | B26: ='Lion''s Mane competitors'!J5 | C26: ='Lion''s Mane competitors'!I5 | D26: ='Lion''s Mane competitors'!K5 | E26: =ROUND(D26/1000*$B$10*30,2)
A27: ='Lion''s Mane competitors'!B8&" – "&'Lion''s Mane competitors'!C8 | B27: ='Lion''s Mane competitors'!J8 | C27: ='Lion''s Mane competitors'!I8 | D27: ='Lion''s Mane competitors'!K8 | E27: =ROUND(D27/1000*$B$10*30,2)
A28: ='Lion''s Mane competitors'!B11&" – "&'Lion''s Mane competitors'!C11 | B28: ='Lion''s Mane competitors'!J11 | C28: ='Lion''s Mane competitors'!I11 | D28: ='Lion''s Mane competitors'!K11 | E28: =ROUND(D28/1000*$B$10*30,2)
A30: Notes
A31: COST IS A PLACEHOLDER: Supliful's page hides the price from us. Send the price screenshot and update B3–B5.
A32: Supliful formula: 1,000 mg organic fruiting body AND mycelium powder per 2 capsules, 'standardised to 40% polysaccharides (400 mg)'. No beta-glucan figure.
A33: Polysaccharides include starch from the grain mycelium is grown on; beta-glucans are the meaningful measure. Ask Supliful for a beta-glucan COA.
A34: Human studies used ~1 g (Saitsu 2019 used 3.2 g/day of fruiting body powder; Mori 2009 used 3 g/day). 1 g/day is at the low end.
A35: Per-mg is comparable with Cortex and Brainstorm (both 1,000 mg) but not with extracts like Eversio 8:1, which are far more concentrated.
A36: Competitor prices from Google Shopping on 28 Oct 2026; they change often.

Sheet Methylene Blue competitors
A1: Google Shopping, 'methylene blue drops', Denver CO, 28 Oct 2026 (sponsored carousel, 16 listings). Days assume ~10 mg/day (1 mL of a 1% solution) unless stated. ~ = assumed.
A2: # | B2: Brand | C2: Product | D2: Format | E2: Count | F2: Servings (days) | G2: Price $ | H2: Was $ | I2: Price per day $ | J2: Methylene blue mg/day | K2: $ per 1,000 mg | L2: Rating | M2: Reviews | N2: Seller | O2: Tier | P2: Lead angle / badges | Q2: Look | R2: Notes
A3: 1 | B3: Compass Lab | C3: Methylene Blue 1% solution, USP grade | D3: Drops | G3: 30.9 | I3: =IF(OR(F3="",G3=""),"",ROUND(G3/F3,2)) | K3: =IF(OR(J3="",I3=""),"",ROUND(I3/J3*1000,2)) | N3: Compass Lab | O3: Drops | P3: USP grade | Q3: Amber dropper, navy + bright blue circle | R3: Bottle size not visible
A4: 2 | B4: ThistleDew Vitality | C4: Premium Methylene Blue USP 10 mg/mL, 2 fl oz | D4: Drops | E4: 60 | F4: 60 | G4: 35.95 | I4: =IF(OR(F4="",G4=""),"",ROUND(G4/F4,2)) | J4: 10 | K4: =IF(OR(J4="",I4=""),"",ROUND(I4/J4*1000,2)) | N4: ThistleDew | O4: Drops | P4: USP grade, free shipping | Q4: Blue glass, cream label | R4: 600 mg per bottle
A5: 3 | B5: Vitasy | C5: Cortex Methylene Blue Drops 10 mg | D5: Drops | E5: 30 | F5: 30 | G5: 24.99 | I5: =IF(OR(F5="",G5=""),"",ROUND(G5/F5,2)) | J5: 10 | K5: =IF(OR(J5="",I5=""),"",ROUND(I5/J5*1000,2)) | N5: Vitasy | O5: Drops | P5: 'Promotes cognitive wellness', free shipping | Q5: Blue glass, navy label | R5: ~1 fl oz assumed
A6: 4 | B6: AccuaBoost | C6: Methylene Blue 1% USP, 1 fl oz | D6: Drops | E6: 30 | F6: 30 | G6: 39.99 | I6: =IF(OR(F6="",G6=""),"",ROUND(G6/F6,2)) | J6: 10 | K6: =IF(OR(J6="",I6=""),"",ROUND(I6/J6*1000,2)) | L6: 4.9 | M6: 9k+ | N6: AccuaBoost | O6: Drops | P6: 'Best...' title, 9k+ reviews | Q6: Blue glass, black label, moody photo | R6: 300 mg per bottle
A7: 5 | B7: Compass Lab | C7: Methylene Blue 0.5% solution | D7: Drops | G7: 29.58 | I7: =IF(OR(F7="",G7=""),"",ROUND(G7/F7,2)) | K7: =IF(OR(J7="",I7=""),"",ROUND(I7/J7*1000,2)) | N7: Compass Lab | O7: Drops | P7: Half strength | Q7: Amber dropper, blue circle | R7: Bottle size not visible
A8: 6 | B8: Heisen Blue | C8: HeisenBlue 2,400 mg per bottle | D8: Drops | F8: 240 | G8: 59.99 | I8: =IF(OR(F8="",G8=""),"",ROUND(G8/F8,2)) | J8: 10 | K8: =IF(OR(J8="",I8=""),"",ROUND(I8/J8*1000,2)) | L8: 4.8 | M8: 500+ | N8: Heisen Blue | O8: Drops | P8: '94% felt results within 3 weeks', buy 1 get travel size free, 30-day guarantee | Q8: Busy infographic image | R8: ~240 days at 10 mg; Canadian
A9: 7 | B9: Heisen Blue | C9: 1% Methylene Blue 1,200 mg per bottle | D9: Drops | F9: 120 | G9: 49.99 | I9: =IF(OR(F9="",G9=""),"",ROUND(G9/F9,2)) | J9: 10 | K9: =IF(OR(J9="",I9=""),"",ROUND(I9/J9*1000,2)) | N9: Heisen Blue | O9: Drops | P9: No subscription required | Q9: Busy infographic image | R9: ~120 days at 10 mg
A10: 8 | B10: Earth Harmony | C10: Ultimate Methylene Blue USP with nano liquid gold, 2 fl oz | D10: Drops | E10: 60 | G10: 39.95 | I10: =IF(OR(F10="",G10=""),"",ROUND(G10/F10,2)) | K10: =IF(OR(J10="",I10=""),"",ROUND(I10/J10*1000,2)) | L10: 4.4 | M10: 826 | N10: Earth Harmony | O10: Drops | P10: Gold + MB combo | Q10: Black dropper, green botanical label | R10: Concentration not visible
A11: 9 | B11: PeakForce Labs | C11: Methylene Blue 20 mg, 60 capsules | D11: Capsule | E11: 60 | F11: 60 | G11: 79 | I11: =IF(OR(F11="",G11=""),"",ROUND(G11/F11,2)) | J11: 20 | K11: =IF(OR(J11="",I11=""),"",ROUND(I11/J11*1000,2)) | N11: PAProducts | O11: Research-use | P11: 'FOR RESEARCH USE ONLY' on label | Q11: Black bottle, bold white type | R11: Red flag: research-use labelling
A12: 10 | B12: Mile High Compounds | C12: Methylene Blue 20 mg, 60 capsules | D12: Capsule | E12: 60 | F12: 60 | G12: 79.99 | I12: =IF(OR(F12="",G12=""),"",ROUND(G12/F12,2)) | J12: 20 | K12: =IF(OR(J12="",I12=""),"",ROUND(I12/J12*1000,2)) | N12: Mile High | O12: Research-use | P12: 'For research use only', free gift | Q12: Clear bottle, blue sky photo | R12: Red flag: research-use labelling
A13: 11 | B13: BioEdge Research | C13: Methylene Blue 10 mg, 60 count | D13: Capsule | E13: 60 | F13: 60 | G13: 79 | I13: =IF(OR(F13="",G13=""),"",ROUND(G13/F13,2)) | J13: 10 | K13: =IF(OR(J13="",I13=""),"",ROUND(I13/J13*1000,2)) | N13: BioEdge | O13: Research-use | P13: 'FOR RESEARCH USE ONLY' (peptide seller) | Q13: White bottle, blue/green | R13: Red flag: research-use labelling
A14: 12 | B14: algorx | C14: Methylene Blue 5 mg / 10 mg capsules | D14: Capsule | G14: 49 | I14: =IF(OR(F14="",G14=""),"",ROUND(G14/F14,2)) | K14: =IF(OR(J14="",I14=""),"",ROUND(I14/J14*1000,2)) | N14: algorx | O14: Rx-style | P14: Pharmacy-style bottle, special offer | Q14: Orange Rx vial | R14: Telehealth/compounding style
A15: 13 | B15: Compass Lab | C15: Methylene Blue 1% refill, 237 mL | D15: Drops (refill) | E15: 237 | F15: 237 | G15: 147.33 | I15: =IF(OR(F15="",G15=""),"",ROUND(G15/F15,2)) | J15: 10 | K15: =IF(OR(J15="",I15=""),"",ROUND(I15/J15*1000,2)) | N15: Compass Lab | O15: Bulk | P15: Refill size | Q15: Large amber bottle | R15: 2,370 mg
A16: 14 | B16: Quantum Innovation Labs | C16: Methylene Blue kit (powder + bottles) | D16: Powder kit | G16: 64.99 | I16: =IF(OR(F16="",G16=""),"",ROUND(G16/F16,2)) | K16: =IF(OR(J16="",I16=""),"",ROUND(I16/J16*1000,2)) | L16: 4.7 | M16: 28 | N16: Quantum | O16: Bulk | P16: DIY kit: mix your own | Q16: Purple box, beakers | R16: Not comparable per mg
A17: 15 | B17: Quantum Innovation Labs | C17: Methylene Blue for Humans, USP powder 100 g | D17: Powder | G17: 164.99 | H17: 200 | I17: =IF(OR(F17="",G17=""),"",ROUND(G17/F17,2)) | K17: =IF(OR(J17="",I17=""),"",ROUND(I17/J17*1000,2)) | L17: 4.9 | M17: 22 | N17: Quantum | O17: Bulk | P17: SALE, 'for humans' | Q17: Purple jar | R17: 100,000 mg: bulk chemical
A18: 16 | B18: Noovit (Supliful) | C18: Methylene Blue Drops 10 mg/mL, 60 mL | D18: Drops | E18: 60 | F18: 60 | G18: 36 | I18: =IF(OR(F18="",G18=""),"",ROUND(G18/F18,2)) | J18: 10 | K18: =IF(OR(J18="",I18=""),"",ROUND(I18/J18*1000,2)) | N18: noovit.com | O18: Drops | P18: — | Q18: Label option B | R18: 600 mg per bottle; 1 mL (20 drops) a day

Sheet Methylene Blue tiers
A1: Tier | B1: Listings | C1: Min price $ | D1: Median price $ | E1: Max price $ | F1: Avg price/day $ | G1: Who | H1: Implication for Noovit
A2: Drops | B2: =COUNTIF('Methylene Blue competitors'!O$3:O$18,A2) | C2: =_xlfn.MINIFS('Methylene Blue competitors'!G$3:G$18,'Methylene Blue competitors'!O$3:O$18,A2) | D2: {=MEDIAN(IF(('Methylene Blue competitors'!O$3:O$18=A2)*('Methylene Blue competitors'!G$3:G$18<>""),'Methylene Blue competitors'!G$3:G$18))} | E2: =_xlfn.MAXIFS('Methylene Blue competitors'!G$3:G$18,'Methylene Blue competitors'!O$3:O$18,A2) | F2: =IFERROR(ROUND(AVERAGEIFS('Methylene Blue competitors'!I$3:I$18,'Methylene Blue competitors'!O$3:O$18,A2),2),"") | G2: Compass Lab, ThistleDew, Cortex, AccuaBoost, Heisen Blue, Earth Harmony | H2: Where a Supliful product would sit: $25–60, median ~$37
A3: Research-use | B3: =COUNTIF('Methylene Blue competitors'!O$3:O$18,A3) | C3: =_xlfn.MINIFS('Methylene Blue competitors'!G$3:G$18,'Methylene Blue competitors'!O$3:O$18,A3) | D3: {=MEDIAN(IF(('Methylene Blue competitors'!O$3:O$18=A3)*('Methylene Blue competitors'!G$3:G$18<>""),'Methylene Blue competitors'!G$3:G$18))} | E3: =_xlfn.MAXIFS('Methylene Blue competitors'!G$3:G$18,'Methylene Blue competitors'!O$3:O$18,A3) | F3: =IFERROR(ROUND(AVERAGEIFS('Methylene Blue competitors'!I$3:I$18,'Methylene Blue competitors'!O$3:O$18,A3),2),"") | G3: PeakForce, Mile High, BioEdge ('for research use only') | H3: Grey market: a sign sellers know it's not a clean supplement
A4: Rx-style | B4: =COUNTIF('Methylene Blue competitors'!O$3:O$18,A4) | C4: =_xlfn.MINIFS('Methylene Blue competitors'!G$3:G$18,'Methylene Blue competitors'!O$3:O$18,A4) | D4: {=MEDIAN(IF(('Methylene Blue competitors'!O$3:O$18=A4)*('Methylene Blue competitors'!G$3:G$18<>""),'Methylene Blue competitors'!G$3:G$18))} | E4: =_xlfn.MAXIFS('Methylene Blue competitors'!G$3:G$18,'Methylene Blue competitors'!O$3:O$18,A4) | F4: =IFERROR(ROUND(AVERAGEIFS('Methylene Blue competitors'!I$3:I$18,'Methylene Blue competitors'!O$3:O$18,A4),2),"") | G4: algorx | H4: Pharmacy / telehealth positioning
A5: Bulk | B5: =COUNTIF('Methylene Blue competitors'!O$3:O$18,A5) | C5: =_xlfn.MINIFS('Methylene Blue competitors'!G$3:G$18,'Methylene Blue competitors'!O$3:O$18,A5) | D5: {=MEDIAN(IF(('Methylene Blue competitors'!O$3:O$18=A5)*('Methylene Blue competitors'!G$3:G$18<>""),'Methylene Blue competitors'!G$3:G$18))} | E5: =_xlfn.MAXIFS('Methylene Blue competitors'!G$3:G$18,'Methylene Blue competitors'!O$3:O$18,A5) | F5: =IFERROR(ROUND(AVERAGEIFS('Methylene Blue competitors'!I$3:I$18,'Methylene Blue competitors'!O$3:O$18,A5),2),"") | G5: Compass refill, Quantum powder and kits | H5: Not our lane

Sheet Methylene Blue profit
A1: Methylene Blue 60 mL drops via Supliful. Orange cells are inputs: change them and everything recalculates.
A3: Landed cost per bottle, free plan $ (PLACEHOLDER: send Supliful's price) | B3: 10.5
A4: Landed cost per bottle, Pro plan $ (PLACEHOLDER) | B4: 7.5
A5: Extra bottle in same order $ (product only, PLACEHOLDER) | B5: 4
A6: Stripe fee % | B6: 0.029
A7: Stripe fixed fee per order $ | B7: 0.3
A8: Ad cost to win a new customer $ (estimate) | B8: 18
A9: Supliful Pro monthly fee $ | B9: 69
A10: Noovit Methylene blue mg/day | B10: 10
A11: Pro break-even (bottles per month) | B11: =ROUND(B9/(B3-B4),0)
A13: Offer | B13: Bottles in order | C13: Price per bottle $ | D13: Order revenue $ | E13: Landed cost, free $ | F13: Stripe $ | G13: Profit, free $ | H13: Margin, free | I13: Landed cost, Pro $ | J13: Profit, Pro $ | K13: Margin, Pro | L13: Profit after ad cost (first order, free) $ | M13: $ per 1,000 mg
A14: One-time | B14: 1 | C14: 36 | D14: =B14*C14 | E14: =$B$3+(B14-1)*$B$5 | F14: =ROUND(D14*$B$6+$B$7,2) | G14: =D14-E14-F14 | H14: =G14/D14 | I14: =$B$4+(B14-1)*$B$5 | J14: =D14-I14-F14 | K14: =J14/D14 | L14: =G14-$B$8 | M14: =ROUND(C14/60/$B$10*1000,2)
A15: One-time (low) | B15: 1 | C15: 30 | D15: =B15*C15 | E15: =$B$3+(B15-1)*$B$5 | F15: =ROUND(D15*$B$6+$B$7,2) | G15: =D15-E15-F15 | H15: =G15/D15 | I15: =$B$4+(B15-1)*$B$5 | J15: =D15-I15-F15 | K15: =J15/D15 | L15: =G15-$B$8 | M15: =ROUND(C15/60/$B$10*1000,2)
A16: Subscribe | B16: 1 | C16: 32 | D16: =B16*C16 | E16: =$B$3+(B16-1)*$B$5 | F16: =ROUND(D16*$B$6+$B$7,2) | G16: =D16-E16-F16 | H16: =G16/D16 | I16: =$B$4+(B16-1)*$B$5 | J16: =D16-I16-F16 | K16: =J16/D16 | L16: =G16-$B$8 | M16: =ROUND(C16/60/$B$10*1000,2)
A17: 3-pack one-time | B17: 3 | C17: 32 | D17: =B17*C17 | E17: =$B$3+(B17-1)*$B$5 | F17: =ROUND(D17*$B$6+$B$7,2) | G17: =D17-E17-F17 | H17: =G17/D17 | I17: =$B$4+(B17-1)*$B$5 | J17: =D17-I17-F17 | K17: =J17/D17 | L17: =G17-$B$8 | M17: =ROUND(C17/60/$B$10*1000,2)
A20: Per-mg comparison: price per bottle Noovit would need to match each competitor's $ per 1,000 mg (at B10 mg/day, 60 days per bottle)
A21: Competitor | B21: Their mg/day | C21: Their price/day $ | D21: Their $ per 1,000 mg | E21: Noovit price to match $
A22: ='Methylene Blue competitors'!B4&" – "&'Methylene Blue competitors'!C4 | B22: ='Methylene Blue competitors'!J4 | C22: ='Methylene Blue competitors'!I4 | D22: ='Methylene Blue competitors'!K4 | E22: =ROUND(D22/1000*$B$10*60,2)
A23: ='Methylene Blue competitors'!B5&" – "&'Methylene Blue competitors'!C5 | B23: ='Methylene Blue competitors'!J5 | C23: ='Methylene Blue competitors'!I5 | D23: ='Methylene Blue competitors'!K5 | E23: =ROUND(D23/1000*$B$10*60,2)
A24: ='Methylene Blue competitors'!B6&" – "&'Methylene Blue competitors'!C6 | B24: ='Methylene Blue competitors'!J6 | C24: ='Methylene Blue competitors'!I6 | D24: ='Methylene Blue competitors'!K6 | E24: =ROUND(D24/1000*$B$10*60,2)
A25: ='Methylene Blue competitors'!B8&" – "&'Methylene Blue competitors'!C8 | B25: ='Methylene Blue competitors'!J8 | C25: ='Methylene Blue competitors'!I8 | D25: ='Methylene Blue competitors'!K8 | E25: =ROUND(D25/1000*$B$10*60,2)
A26: ='Methylene Blue competitors'!B9&" – "&'Methylene Blue competitors'!C9 | B26: ='Methylene Blue competitors'!J9 | C26: ='Methylene Blue competitors'!I9 | D26: ='Methylene Blue competitors'!K9 | E26: =ROUND(D26/1000*$B$10*60,2)
A27: ='Methylene Blue competitors'!B11&" – "&'Methylene Blue competitors'!C11 | B27: ='Methylene Blue competitors'!J11 | C27: ='Methylene Blue competitors'!I11 | D27: ='Methylene Blue competitors'!K11 | E27: =ROUND(D27/1000*$B$10*60,2)
A28: ='Methylene Blue competitors'!B12&" – "&'Methylene Blue competitors'!C12 | B28: ='Methylene Blue competitors'!J12 | C28: ='Methylene Blue competitors'!I12 | D28: ='Methylene Blue competitors'!K12 | E28: =ROUND(D28/1000*$B$10*60,2)
A29: ='Methylene Blue competitors'!B13&" – "&'Methylene Blue competitors'!C13 | B29: ='Methylene Blue competitors'!J13 | C29: ='Methylene Blue competitors'!I13 | D29: ='Methylene Blue competitors'!K13 | E29: =ROUND(D29/1000*$B$10*60,2)
A30: ='Methylene Blue competitors'!B15&" – "&'Methylene Blue competitors'!C15 | B30: ='Methylene Blue competitors'!J15 | C30: ='Methylene Blue competitors'!I15 | D30: ='Methylene Blue competitors'!K15 | E30: =ROUND(D30/1000*$B$10*60,2)
A32: Notes
A33: RECOMMENDATION: do not sell yet. See docs/SHOPPING_ANALYSIS_METHYLENE_BLUE.md (regulatory status, serotonin interaction, G6PD).
A34: COST IS A PLACEHOLDER: Supliful's page hides the price.
A35: Supliful: 10 mg methylene blue per 1 mL serving, 60 mL bottle (600 mg, 60 servings at 1 mL/day). USP grade not stated.
A36: Per mg, a $36 bottle (~$6 per 100 mg) is in line with ThistleDew and the 1% drops; price is not the problem here.
A37: Competitor prices from Google Shopping on 28 Oct 2026; they change often.

Sheet NAD+ competitors
A1: Google Shopping, 'nad +', Denver CO, 28 Oct 2026 (sponsored carousel, 13 listings). Vials are lyophilised powder for injection sold 'for research use only' - not comparable with oral supplements. ~ = assumed.
A2: # | B2: Brand | C2: Product | D2: Format | E2: Count | F2: Servings (days) | G2: Price $ | H2: Was $ | I2: Price per day $ | J2: NAD+ mg/day | K2: $ per 1,000 mg | L2: Rating | M2: Reviews | N2: Seller | O2: Tier | P2: Lead angle / badges | Q2: Look | R2: Notes
A3: 1 | B3: Vitasy | C3: Cortex NAD+ 60 capsules | D3: Capsule | E3: 60 | F3: 30 | G3: 39.99 | I3: =IF(OR(F3="",G3=""),"",ROUND(G3/F3,2)) | J3: 500 | K3: =IF(OR(J3="",I3=""),"",ROUND(I3/J3*1000,2)) | N3: Vitasy | O3: Oral capsule | P3: 'Aids in normal aging process, promotes normal cell function, supports cardiovascular health'; free shipping | Q3: Dark navy label, white bottle | R3: Very likely the same Supliful formula; mg assumed
A4: 2 | B4: Elysium Health | C4: Basis (NR + pterostilbene), 60 capsules | D4: Capsule | E4: 60 | F4: 30 | G4: 65 | I4: =IF(OR(F4="",G4=""),"",ROUND(G4/F4,2)) | K4: =IF(OR(J4="",I4=""),"",ROUND(I4/J4*1000,2)) | L4: 4.3 | M4: 1k+ | N4: Elysium | O4: Oral capsule | P4: 'Boost NAD+ levels', clinical trials on NR | Q4: Minimal white jar, capsules falling | R4: NR, not NAD+: not comparable per mg
A5: 3 | B5: Innerbody Labs | C5: NAD+ Support (multi-bottle) | D5: Capsule | G5: 222 | I5: =IF(OR(F5="",G5=""),"",ROUND(G5/F5,2)) | K5: =IF(OR(J5="",I5=""),"",ROUND(I5/J5*1000,2)) | N5: Innerbody Labs | O5: Oral capsule | P5: 'For cellular energy and longevity', 'ingredients supported by human research' | Q5: Amber glass, white minimal label | R5: Likely 3-bottle pack
A6: 4 | B6: Global Healing | C6: Microsomal NAD+ liquid, 2 fl oz | D6: Oral liquid | E6: 60 | G6: 42.95 | I6: =IF(OR(F6="",G6=""),"",ROUND(G6/F6,2)) | K6: =IF(OR(J6="",I6=""),"",ROUND(I6/J6*1000,2)) | N6: Global Healing | O6: Oral liquid | P6: Free gift w/ $75+ | Q6: Dark green dropper
A7: 5 | B7: Data Peptides | C7: NAD+ 500 mg vial | D7: Vial (injectable) | G7: 40 | I7: =IF(OR(F7="",G7=""),"",ROUND(G7/F7,2)) | K7: =IF(OR(J7="",I7=""),"",ROUND(I7/J7*1000,2)) | N7: Data Peptides | O7: Research vial | P7: '99% purity, lab tested, research use only'; 1st order $32 | Q7: Designer box, blue blobs | R7: Grey market
A8: 6 | B8: Peak Lab Peptides | C8: NAD+ 500 mg vial | D8: Vial (injectable) | G8: 23 | I8: =IF(OR(F8="",G8=""),"",ROUND(G8/F8,2)) | K8: =IF(OR(J8="",I8=""),"",ROUND(I8/J8*1000,2)) | N8: peaklabpeptides | O8: Research vial | P8: 'Third party lab verified >99% purity' | Q8: Black label vial | R8: Grey market
A9: 7 | B9: Peak Lab Peptides | C9: NAD+ 100 mg vial | D9: Vial (injectable) | G9: 27 | I9: =IF(OR(F9="",G9=""),"",ROUND(G9/F9,2)) | K9: =IF(OR(J9="",I9=""),"",ROUND(I9/J9*1000,2)) | N9: peaklabpeptides | O9: Research vial | P9: — | Q9: Black label vial | R9: Grey market
A10: 8 | B10: Nationwide Peptides | C10: NAD+ 'peptide' 1000 mg | D10: Vial (injectable) | G10: 119 | I10: =IF(OR(F10="",G10=""),"",ROUND(G10/F10,2)) | K10: =IF(OR(J10="",I10=""),"",ROUND(I10/J10*1000,2)) | N10: Nationwide | O10: Research vial | P10: 'Reference material' | Q10: Blue label vial | R10: NAD+ is not a peptide
